Workbook
Name Slicer_Payment_Method: #N/A
Name Slicer_Product_Category: #N/A
Name Slicer_Region: #N/A

Sheet Sheet1
A3: Sum of Total Amount | B3: Column Labels
A4: Row Labels | B4: Books | C4: Electronics | D4: Fashion | E4: Home | F4: Toys | G4: Grand Total
A5: Central | B5: 84 | C5: 2662 | D5: 210 | E5: 2063 | F5: 437 | G5: 5456
A6: East | B6: 394 | C6: 365 | D6: 711 | E6: 741 | F6: 1424 | G6: 3635
A7: North | B7: 464 | C7: 6522 | D7: 788 | E7: 2131 | F7: 586 | G7: 10491
A8: South | B8: 423 | C8: 3938 | D8: 1032 | E8: 1881 | F8: 43 | G8: 7317
A9: West | B9: 350 | C9: 1722 | D9: 1131 | E9: 4135 | F9: 1021 | G9: 8359
A10: Grand Total | B10: 1715 | C10: 15209 | D10: 3872 | E10: 10951 | F10: 3511 | G10: 35258

Sheet Sheet2
A3: Row Labels | B3: Count of Order ID
A4: Cancelled | B4: 30
A5: Delivered | B5: 34
A6: In Transit | B6: 36
A7: Grand Total | B7: 100

Sheet Sheet3
A3: Row Labels | B3: Average of Delivery Time
A4: Central | B4: 4.2
A5: East | B5: 4.25
A6: North | B6: 3.625
A7: South | B7: 3.3333333
A8: West | B8: 3.4285714
A9: Grand Total | B9: 3.7647059

Sheet Sheet4
A3: Count of Order ID | B3: Column Labels
A4: Row Labels | B4: Cancelled | C4: Delivered | D4: Grand Total | E4: Cancellation Rate
A5: Central | B5: 5 | C5: 9 | D5: 14 | E5: =B5/D5 -> 0.35714286
A6: East | B6: 3 | C6: 15 | D6: 18 | E6: =B6/D6 -> 0.16666667
A7: North | B7: 10 | C7: 15 | D7: 25 | E7: =B7/D7 -> 0.4
A8: South | B8: 4 | C8: 16 | D8: 20 | E8: =B8/D8 -> 0.2
A9: West | B9: 8 | C9: 15 | D9: 23 | E9: =B9/D9 -> 0.34782609
A10: Grand Total | B10: 30 | C10: 70 | D10: 100 | E10: =B10/D10 -> 0.3

Sheet Sheet6
A3: Sum of Effective Sales
A4: 3010

Sheet sales by region
A3: Row Labels | B3: Sum of Total Amount
A4: Central | B4: 5456
A5: Grand Total | B5: 5456

Sheet sale by product catagory
A3: Row Labels | B3: Sum of Total Amount
A4: Books | B4: 84
A5: Electronics | B5: 2662
A6: Fashion | B6: 210
A7: Home | B7: 2063
A8: Toys | B8: 437
A9: Grand Total | B9: 5456

Sheet order by delivery status
A3: Row Labels | B3: Count of Order ID
A4: Cancelled | B4: 5
A5: Delivered | B5: 5
A6: In Transit | B6: 4
A7: Grand Total | B7: 14

Sheet Sheet12
W17: Sum of Total Amount
W18: 5456
W20: =Sheet17!C5 -> 0.071428571
W22: Electronics
W28: North

Sheet Sheet14
A3: Row Labels | B3: Sum of Total Amount
A4: Central | B4: 5456
A5: Grand Total | B5: 5456

Sheet Sheet15
A3: Row Labels | B3: Sum of Total Amount
A4: Books | B4: 84
A5: Electronics | B5: 2662
A6: Fashion | B6: 210
A7: Home | B7: 2063
A8: Toys | B8: 437
A9: Grand Total | B9: 5456

Sheet Sheet16
A3: Sum of Total Amount
A4: 5456

Sheet Sheet17
A3: Row Labels | B3: Count of Order ID
A4: Cancelled | B4: 9
A5: Fast | B5: 1 | C5: =B5/B7 -> 0.071428571
A6: Slow | B6: 4
A7: Grand Total | B7: 14

Sheet Orders
A1: Order ID | B1: Customer ID | C1: Product ID | D1: Region | E1: Sale Price/Unit | F1: Quantity | G1: Total Amount | H1: Payment Method | I1: Delivery Status | J1: Fulfillment Partner | K1: Order Date | L1: Delivery Date | M1: Cancel Date | N1: Order Status | O1: Delivery Time | P1: Delivery Performance | Q1: Customer Name | R1: Product Category | S1: Product Name | T1: Effective Sales
A2: ORD0001 | B2: CUST021 | C2: PROD012 | D2: North | E2: 44 | F2: 1 | G2: 44 | H2: Apple Pay | I2: Cancelled | J2: DHL | K2: 45291 | M2: 45293 | N2: =IF(M2<>"","Cancelled","Delivered") -> Cancelled | O2: =IF(L2<>"",L2-K2,"NA") -> NA | P2: =IF(L2="","Cancelled",IF(L2-K2<=2,"Fast","Slow")) -> Cancelled | Q2: =_xlfn.XLOOKUP(Orders!B2,'Customer Master'!$A$1:$A$50,'Customer Master'!$B$1:$B$50) -> Zoe Mitchell | R2: =_xlfn.XLOOKUP(Orders!C2,'Product Master'!$A$1:$A$23,'Product Master'!$C$1:$C$23) -> Home | S2: =_xlfn.XLOOKUP(C2,'Product Master'!$A$1:$A$23,'Product Master'!$B$1:$B$23) -> Lamp | T2: =IF(I2="Delivered",G2,0) -> 0
A3: ORD0002 | B3: CUST029 | C3: PROD018 | D3: East | E3: 96 | F3: 4 | G3: 384 | H3: Credit Card | I3: Delivered | J3: DHL | K3: 44979 | L3: 44981 | N3: =IF(M3<>"","Cancelled","Delivered") -> Delivered | O3: =IF(L3<>"",L3-K3,"NA") -> 2 | P3: =IF(L3="","Cancelled",IF(L3-K3<=2,"Fast","Slow")) -> Fast | Q3: =_xlfn.XLOOKUP(Orders!B3,'Customer Master'!$A$1:$A$50,'Customer Master'!$B$1:$B$50) -> Ava White | R3: =_xlfn.XLOOKUP(Orders!C3,'Product Master'!$A$1:$A$23,'Product Master'!$C$1:$C$23) -> Toys | S3: =_xlfn.XLOOKUP(C3,'Product Master'!$A$1:$A$23,'Product Master'!$B$1:$B$23) -> Doll House | T3: =IF(I3="Delivered",G3,0) -> 384
A4: ORD0003 | B4: CUST021 | C4: PROD013 | D4: South | E4: 194 | F4: 4 | G4: 776 | H4: Credit Card | I4: In Transit | J4: USPS | K4: 45210 | N4: =IF(M4<>"","Cancelled","Delivered") -> Delivered | O4: =IF(L4<>"",L4-K4,"NA") -> NA | P4: =IF(L4="","Cancelled",IF(L4-K4<=2,"Fast","Slow")) -> Cancelled | Q4: =_xlfn.XLOOKUP(Orders!B4,'Customer Master'!$A$1:$A$50,'Customer Master'!$B$1:$B$50) -> Zoe Mitchell | R4: =_xlfn.XLOOKUP(Orders!C4,'Product Master'!$A$1:$A$23,'Product Master'!$C$1:$C$23) -> Home | S4: =_xlfn.XLOOKUP(C4,'Product Master'!$A$1:$A$23,'Product Master'!$B$1:$B$23) -> Vacuum Cleaner | T4: =IF(I4="Delivered",G4,0) -> 0
A5: ORD0004 | B5: CUST044 | C5: PROD013 | D5: North | E5: 196 | F5: 3 | G5: 588 | H5: PayPal | I5: Cancelled | J5: UPS | K5: 45051 | M5: 45057 | N5: =IF(M5<>"","Cancelled","Delivered") -> Cancelled | O5: =IF(L5<>"",L5-K5,"NA") -> NA | P5: =IF(L5="","Cancelled",IF(L5-K5<=2,"Fast","Slow")) -> Cancelled | Q5: =_xlfn.XLOOKUP(Orders!B5,'Customer Master'!$A$1:$A$50,'Customer Master'!$B$1:$B$50) -> Grace Ward | R5: =_xlfn.XLOOKUP(Orders!C5,'Product Master'!$A$1:$A$23,'Product Master'!$C$1:$C$23) -> Home | S5: =_xlfn.XLOOKUP(C5,'Product Master'!$A$1:$A$23,'Product Master'!$B$1:$B$23) -> Vacuum Cleaner | T5: =IF(I5="Delivered",G5,0) -> 0
A6: ORD0005 | B6: CUST027 | C6: PROD010 | D6: North | E6: 59 | F6: 1 | G6: 59 | H6: PayPal | I6: Delivered | J6: Amazon Logistics | K6: 44959 | L6: 44962 | N6: =IF(M6<>"","Cancelled","Delivered") -> Delivered | O6: =IF(L6<>"",L6-K6,"NA") -> 3 | P6: =IF(L6="","Cancelled",IF(L6-K6<=2,"Fast","Slow")) -> Slow | Q6: =_xlfn.XLOOKUP(Orders!B6,'Customer Master'!$A$1:$A$50,'Customer Master'!$B$1:$B$50) -> Hazel Brooks | R6: =_xlfn.XLOOKUP(Orders!C6,'Product Master'!$A$1:$A$23,'Product Master'!$C$1:$C$23) -> Fashion | S6: =_xlfn.XLOOKUP(C6,'Product Master'!$A$1:$A$23,'Product Master'!$B$1:$B$23) -> Jeans | T6: =IF(I6="Delivered",G6,0) -> 59
A7: ORD0006 | B7: CUST009 | C7: PROD010 | D7: North | E7: 58 | F7: 4 | G7: 232 | H7: Amazon Pay | I7: Cancelled | J7: DHL | K7: 45231 | M7: 45232 | N7: =IF(M7<>"","Cancelled","Delivered") -> Cancelled | O7: =IF(L7<>"",L7-K7,"NA") -> NA | P7: =IF(L7="","Cancelled",IF(L7-K7<=2,"Fast","Slow")) -> Cancelled | Q7: =_xlfn.XLOOKUP(Orders!B7,'Customer Master'!$A$1:$A$50,'Customer Master'!$B$1:$B$50) -> Jackson Allen | R7: =_xlfn.XLOOKUP(Orders!C7,'Product Master'!$A$1:$A$23,'Product Master'!$C$1:$C$23) -> Fashion | S7: =_xlfn.XLOOKUP(C7,'Product Master'!$A$1:$A$23,'Product Master'!$B$1:$B$23) -> Jeans | T7: =IF(I7="Delivered",G7,0) -> 0
A8: ORD0007 | B8: CUST042 | C8: PROD020 | D8: Central | E8: 105 | F8: 3 | G8: 315 | H8: Debit Card | I8: Cancelled | J8: DHL | K8: 45152 | M8: 45156 | N8: =IF(M8<>"","Cancelled","Delivered") -> Cancelled | O8: =IF(L8<>"",L8-K8,"NA") -> NA | P8: =IF(L8="","Cancelled",IF(L8-K8<=2,"Fast","Slow")) -> Cancelled | Q8: =_xlfn.XLOOKUP(Orders!B8,'Customer Master'!$A$1:$A$50,'Customer Master'!$B$1:$B$50) -> Noah Wilson | R8: =_xlfn.XLOOKUP(Orders!C8,'Product Master'!$A$1:$A$23,'Product Master'!$C$1:$C$23) -> Electronics | S8: =_xlfn.XLOOKUP(C8,'Product Master'!$A$1:$A$23,'Product Master'!$B$1:$B$23) -> Bluetooth Speaker | T8: =IF(I8="Delivered",G8,0) -> 0
A9: ORD0008 | B9: CUST019 | C9: PROD021 | D9: West | E9: 37 | F9: 5 | G9: 185 | H9: PayPal | I9: Cancelled | J9: DHL | K9: 45017 | M9: 45022 | N9: =IF(M9<>"","Cancelled","Delivered") -> Cancelled | O9: =IF(L9<>"",L9-K9,"NA") -> NA | P9: =IF(L9="","Cancelled",IF(L9-K9<=2,"Fast","Slow")) -> Cancelled | Q9: =_xlfn.XLOOKUP(Orders!B9,'Customer Master'!$A$1:$A$50,'Customer Master'!$B$1:$B$50) -> Ava Robinson | R9: =_xlfn.XLOOKUP(Orders!C9,'Product Master'!$A$1:$A$23,'Product Master'!$C$1:$C$23) -> Home | S9: =_xlfn.XLOOKUP(C9,'Product Master'!$A$1:$A$23,'Product Master'!$B$1:$B$23) -> Wall Clock | T9: =IF(I9="Delivered",G9,0) -> 0
A10: ORD0009 | B10: CUST013 | C10: PROD019 | D10: Central | E10: 44 | F10: 2 | G10: 88 | H10: Credit Card | I10: In Transit | J10: Amazon Logistics | K10: 45128 | N10: =IF(M10<>"","Cancelled","Delivered") -> Delivered | O10: =IF(L10<>"",L10-K10,"NA") -> NA | P10: =IF(L10="","Cancelled",IF(L10-K10<=2,"Fast","Slow")) -> Cancelled | Q10: =_xlfn.XLOOKUP(Orders!B10,'Customer Master'!$A$1:$A$50,'Customer Master'!$B$1:$B$50) -> Olivia Martinez | R10: =_xlfn.XLOOKUP(Orders!C10,'Product Master'!$A$1:$A$23,'Product Master'!$C$1:$C$23) -> Fashion | S10: =_xlfn.XLOOKUP(C10,'Product Master'!$A$1:$A$23,'Product Master'!$B$1:$B$23) -> Formal Shirt | T10: =IF(I10="Delivered",G10,0) -> 0
A11: ORD0010 | B11: CUST019 | C11: PROD003 | D11: South | E11: 141 | F11: 4 | G11: 564 | H11: Debit Card | I11: In Transit | J11: DHL | K11: 45289 | N11: =IF(M11<>"","Cancelled","Delivered") -> Delivered | O11: =IF(L11<>"",L11-K11,"NA") -> NA | P11: =IF(L11="","Cancelled",IF(L11-K11<=2,"Fast","Slow")) -> Cancelled | Q11: =_xlfn.XLOOKUP(Orders!B11,'Customer Master'!$A$1:$A$50,'Customer Master'!$B$1:$B$50) -> Ava Robinson | R11: =_xlfn.XLOOKUP(Orders!C11,'Product Master'!$A$1:$A$23,'Product Master'!$C$1:$C$23) -> Home | S11: =_xlfn.XLOOKUP(C11,'Product Master'!$A$1:$A$23,'Product Master'!$B$1:$B$23) -> Cookware Set | T11: =IF(I11="Delivered",G11,0) -> 0
A12: ORD0011 | B12: CUST046 | C12: PROD014 | D12: South | E12: 249 | F12: 1 | G12: 249 | H12: Amazon Pay | I12: Cancelled | J12: USPS | K12: 45050 | M12: 45054 | N12: =IF(M12<>"","Cancelled","Delivered") -> Cancelled | O12: =IF(L12<>"",L12-K12,"NA") -> NA | P12: =IF(L12="","Cancelled",IF(L12-K12<=2,"Fast","Slow")) -> Cancelled | Q12: =_xlfn.XLOOKUP(Orders!B12,'Customer Master'!$A$1:$A$50,'Customer Master'!$B$1:$B$50) -> Emily Johnson | R12: =_xlfn.XLOOKUP(Orders!C12,'Product Master'!$A$1:$A$23,'Product Master'!$C$1:$C$23) -> Electronics | S12: =_xlfn.XLOOKUP(C12,'Product Master'!$A$1:$A$23,'Product Master'!$B$1:$B$23) -> Smartwatch | T12: =IF(I12="Delivered",G12,0) -> 0
A13: ORD0012 | B13: CUST045 | C13: PROD014 | D13: Central | E13: 247 | F13: 3 | G13: 741 | H13: Amazon Pay | I13: In Transit | J13: FedEx | K13: 45132 | N13: =IF(M13<>"","Cancelled","Delivered") -> Delivered | O13: =IF(L13<>"",L13-K13,"NA") -> NA | P13: =IF(L13="","Cancelled",IF(L13-K13<=2,"Fast","Slow")) -> Cancelled | Q13: =_xlfn.XLOOKUP(Orders!B13,'Customer Master'!$A$1:$A$50,'Customer Master'!$B$1:$B$50) -> Emily Johnson | R13: =_xlfn.XLOOKUP(Orders!C13,'Product Master'!$A$1:$A$23,'Product Master'!$C$1:$C$23) -> Electronics | S13: =_xlfn.XLOOKUP(C13,'Product Master'!$A$1:$A$23,'Product Master'!$B$1:$B$23) -> Smartwatch | T13: =IF(I13="Delivered",G13,0) -> 0
A14: ORD0013 | B14: CUST023 | C14: PROD006 | D14: Central | E14: 96 | F14: 1 | G14: 96 | H14: Apple Pay | I14: Cancelled | J14: Amazon Logistics | K14: 44982 | M14: 44985 | N14: =IF(M14<>"","Cancelled","Delivered") -> Cancelled | O14: =IF(L14<>"",L14-K14,"NA") -> NA | P14: =IF(L14="","Cancelled",IF(L14-K14<=2,"Fast","Slow")) -> Cancelled | Q14: =_xlfn.XLOOKUP(Orders!B14,'Customer Master'!$A$1:$A$50,'Customer Master'!$B$1:$B$50) -> Charlotte Reed | R14: =_xlfn.XLOOKUP(Orders!C14,'Product Master'!$A$1:$A$23,'Product Master'!$C$1:$C$23) -> Fashion | S14: =_xlfn.XLOOKUP(C14,'Product Master'!$A$1:$A$23,'Product Master'!$B$1:$B$23) -> Shoes | T14: =IF(I14="Delivered",G14,0) -> 0
A15: ORD0014 | B15: CUST033 | C15: PROD017 | D15: West | E15: 74 | F15: 5 | G15: 370 | H15: Apple Pay | I15: Cancelled | J15: Amazon Logistics | K15: 44981 | M15: 44982 | N15: =IF(M15<>"","Cancelled","Delivered") -> Cancelled | O15: =IF(L15<>"",L15-K15,"NA") -> NA | P15: =IF(L15="","Cancelled",IF(L15-K15<=2,"Fast","Slow")) -> Cancelled | Q15: =_xlfn.XLOOKUP(Orders!B15,'Customer Master'!$A$1:$A$50,'Customer Master'!$B$1:$B$50) -> Hazel Rivera | R15: =_xlfn.XLOOKUP(Orders!C15,'Product Master'!$A$1:$A$23,'Product Master'!$C$1:$C$23) -> Electronics | S15: =_xlfn.XLOOKUP(C15,'Product Master'!$A$1:$A$23,'Product Master'!$B$1:$B$23) -> Gaming Mouse | T15: =IF(I15="Delivered",G15,0) -> 0
A16: ORD0015 | B16: CUST033 | C16: PROD005 | D16: South | E16: 27 | F16: 1 | G16: 27 | H16: Credit Card | I16: Cancelled | J16: Amazon Logistics | K16: 45164 | M16: 45171 | N16: =IF(M16<>"","Cancelled","Delivered") -> Cancelled | O16: =IF(L16<>"",L16-K16,"NA") -> NA | P16: =IF(L16="","Cancelled",IF(L16-K16<=2,"Fast","Slow")) -> Cancelled | Q16: =_xlfn.XLOOKUP(Orders!B16,'Customer Master'!$A$1:$A$50,'Customer Master'!$B$1:$B$50) -> Hazel Rivera | R16: =_xlfn.XLOOKUP(Orders!C16,'Product Master'!$A$1:$A$23,'Product Master'!$C$1:$C$23) -> Fashion | S16: =_xlfn.XLOOKUP(C16,'Product Master'!$A$1:$A$23,'Product Master'!$B$1:$B$23) -> T-Shirt | T16: =IF(I16="Delivered",G16,0) -> 0
A17: ORD0016 | B17: CUST047 | C17: PROD005 | D17: South | E17: 27 | F17: 3 | G17: 81 | H17: Debit Card | I17: In Transit | J17: Amazon Logistics | K17: 44970 | N17: =IF(M17<>"","Cancelled","Delivered") -> Delivered | O17: =IF(L17<>"",L17-K17,"NA") -> NA | P17: =IF(L17="","Cancelled",IF(L17-K17<=2,"Fast","Slow")) -> Cancelled | Q17: =_xlfn.XLOOKUP(Orders!B17,'Customer Master'!$A$1:$A$50,'Customer Master'!$B$1:$B$50) -> Scarlett Murphy | R17: =_xlfn.XLOOKUP(Orders!C17,'Product Master'!$A$1:$A$23,'Product Master'!$C$1:$C$23) -> Fashion | S17: =_xlfn.XLOOKUP(C17,'Product Master'!$A$1:$A$23,'Product Master'!$B$1:$B$23) -> T-Shirt | T17: =IF(I17="Delivered",G17,0) -> 0
A18: ORD0017 | B18: CUST045 | C18: PROD015 | D18: East | E18: 21 | F18: 3 | G18: 63 | H18: Credit Card | I18: Delivered | J18: DHL | K18: 45105 | L18: 45108 | N18: =IF(M18<>"","Cancelled","Delivered") -> Delivered | O18: =IF(L18<>"",L18-K18,"NA") -> 3 | P18: =IF(L18="","Cancelled",IF(L18-K18<=2,"Fast","Slow")) -> Slow | Q18: =_xlfn.XLOOKUP(Orders!B18,'Customer Master'!$A$1:$A$50,'Customer Master'!$B$1:$B$50) -> Emily Johnson | R18: =_xlfn.XLOOKUP(Orders!C18,'Product Master'!$A$1:$A$23,'Product Master'!$C$1:$C$23) -> Books | S18: =_xlfn.XLOOKUP(C18,'Product Master'!$A$1:$A$23,'Product Master'!$B$1:$B$23) -> Novel | T18: =IF(I18="Delivered",G18,0) -> 63
A19: ORD0018 | B19: CUST011 | C19: PROD008 | D19: West | E19: 70 | F19: 5 | G19: 350 | H19: PayPal | I19: In Transit | J19: Amazon Logistics | K19: 45258 | N19: =IF(M19<>"","Cancelled","Delivered") -> Delivered | O19: =IF(L19<>"",L19-K19,"NA") -> NA | P19: =IF(L19="","Cancelled",IF(L19-K19<=2,"Fast","Slow")) -> Cancelled | Q19: =_xlfn.XLOOKUP(Orders!B19,'Customer Master'!$A$1:$A$50,'Customer Master'!$B$1:$B$50) -> Mason Hall | R19: =_xlfn.XLOOKUP(Orders!C19,'Product Master'!$A$1:$A$23,'Product Master'!$C$1:$C$23) -> Books | S19: =_xlfn.XLOOKUP(C19,'Product Master'!$A$1:$A$23,'Product Master'!$B$1:$B$23) -> Textbook | T19: =IF(I19="Delivered",G19,0) -> 0
A20: ORD0019 | B20: CUST041 | C20: PROD006 | D20: South | E20: 94 | F20: 4 | G20: 376 | H20: Credit Card | I20: In Transit | J20: USPS | K20: 45163 | N20: =IF(M20<>"","Cancelled","Delivered") -> Delivered | O20: =IF(L20<>"",L20-K20,"NA") -> NA | P20: =IF(L20="","Cancelled",IF(L20-K20<=2,"Fast","Slow")) -> Cancelled | Q20: =_xlfn.XLOOKUP(Orders!B20,'Customer Master'!$A$1:$A$50,'Customer Master'!$B$1:$B$50) -> Jacob Price | R20: =_xlfn.XLOOKUP(Orders!C20,'Product Master'!$A$1:$A$23,'Product Master'!$C$1:$C$23) -> Fashion | S20: =_xlfn.XLOOKUP(C20,'Product Master'!$A$1:$A$23,'Product Master'!$B$1:$B$23) -> Shoes | T20: =IF(I20="Delivered",G20,0) -> 0
A21: ORD0020 | B21: CUST025 | C21: PROD001 | D21: North | E21: 813 | F21: 2 | G21: 1626 | H21: Credit Card | I21: In Transit | J21: FedEx | K21: 45028 | N21: =IF(M21<>"","Cancelled","Delivered") -> Delivered | O21: =IF(L21<>"",L21-K21,"NA") -> NA | P21: =IF(L21="","Cancelled",IF(L21-K21<=2,"Fast","Slow")) -> Cancelled | Q21: =_xlfn.XLOOKUP(Orders!B21,'Customer Master'!$A$1:$A$50,'Customer Master'!$B$1:$B$50) -> Emma King | R21: =_xlfn.XLOOKUP(Orders!C21,'Product Master'!$A$1:$A$23,'Product Master'!$C$1:$C$23) -> Electronics | S21: =_xlfn.XLOOKUP(C21,'Product Master'!$A$1:$A$23,'Product Master'!$B$1:$B$23) -> Smartphone | T21: =IF(I21="Delivered",G21,0) -> 0
A22: ORD0021 | B22: CUST013 | C22: PROD015 | D22: Central | E22: 21 | F22: 4 | G22: 84 | H22: PayPal | I22: In Transit | J22: Amazon Logistics | K22: 45201 | N22: =IF(M22<>"","Cancelled","Delivered") -> Delivered | O22: =IF(L22<>"",L22-K22,"NA") -> NA | P22: =IF(L22="","Cancelled",IF(L22-K22<=2,"Fast","Slow")) -> Cancelled | Q22: =_xlfn.XLOOKUP(Orders!B22,'Customer Master'!$A$1:$A$50,'Customer Master'!$B$1:$B$50) -> Olivia Martinez | R22: =_xlfn.XLOOKUP(Orders!C22,'Product Master'!$A$1:$A$23,'Product Master'!$C$1:$C$23) -> Books | S22: =_xlfn.XLOOKUP(C22,'Product Master'!$A$1:$A$23,'Product Master'!$B$1:$B$23) -> Novel | T22: =IF(I22="Delivered",G22,0) -> 0
A23: ORD0022 | B23: CUST023 | C23: PROD012 | D23: West | E23: 46 | F23: 5 | G23: 230 | H23: PayPal | I23: In Transit | J23: USPS | K23: 45239 | N23: =IF(M23<>"","Cancelled","Delivered") -> Delivered | O23: =IF(L23<>"",L23-K23,"NA") -> NA | P23: =IF(L23="","Cancelled",IF(L23-K23<=2,"Fast","Slow")) -> Cancelled | Q23: =_xlfn.XLOOKUP(Orders!B23,'Customer Master'!$A$1:$A$50,'Customer Master'!$B$1:$B$50) -> Charlotte Reed | R23: =_xlfn.XLOOKUP(Orders!C23,'Product Master'!$A$1:$A$23,'Product Master'!$C$1:$C$23) -> Home | S23: =_xlfn.XLOOKUP(C23,'Product Master'!$A$1:$A$23,'Product Master'!$B$1:$B$23) -> Lamp | T23: =IF(I23="Delivered",G23,0) -> 0
A24: ORD0023 | B24: CUST016 | C24: PROD010 | D24: West | E24: 58 | F24: 3 | G24: 174 | H24: Amazon Pay | I24: Cancelled | J24: Amazon Logistics | K24: 44970 | M24: 44971 | N24: =IF(M24<>"","Cancelled","Delivered") -> Cancelled | O24: =IF(L24<>"",L24-K24,"NA") -> NA | P24: =IF(L24="","Cancelled",IF(L24-K24<=2,"Fast","Slow")) -> Cancelled | Q24: =_xlfn.XLOOKUP(Orders!B24,'Customer Master'!$A$1:$A$50,'Customer Master'!$B$1:$B$50) -> Elijah Lewis | R24: =_xlfn.XLOOKUP(Orders!C24,'Product Master'!$A$1:$A$23,'Product Master'!$C$1:$C$23) -> Fashion | S24: =_xlfn.XLOOKUP(C24,'Product Master'!$A$1:$A$23,'Product Master'!$B$1:$B$23) -> Jeans | T24: =IF(I24="Delivered",G24,0) -> 0
A25: ORD0024 | B25: CUST028 | C25: PROD006 | D25: West | E25: 96 | F25: 5 | G25: 480 | H25: Amazon Pay | I25: Delivered | J25: Amazon Logistics | K25: 45232 | L25: 45235 | N25: =IF(M25<>"","Cancelled","Delivered") -> Delivered | O25: =IF(L25<>"",L25-K25,"NA") -> 3 | P25: =IF(L25="","Cancelled",IF(L25-K25<=2,"Fast","Slow")) -> Slow | Q25: =_xlfn.XLOOKUP(Orders!B25,'Customer Master'!$A$1:$A$50,'Customer Master'!$B$1:$B$50) -> Lily Bennett | R25: =_xlfn.XLOOKUP(Orders!C25,'Product Master'!$A$1:$A$23,'Product Master'!$C$1:$C$23) -> Fashion | S25: =_xlfn.XLOOKUP(C25,'Product Master'!$A$1:$A$23,'Product Master'!$B$1:$B$23) -> Shoes | T25: =IF(I25="Delivered",G25,0) -> 480
A26: ORD0025 | B26: CUST040 | C26: PROD002 | D26: South | E26: 43 | F26: 1 | G26: 43 | H26: Debit Card | I26: Delivered | J26: Amazon Logistics | K26: 45074 | L26: 45076 | N26: =IF(M26<>"","Cancelled","Delivered") -> Delivered | O26: =IF(L26<>"",L26-K26,"NA") -> 2 | P26: =IF(L26="","Cancelled",IF(L26-K26<=2,"Fast","Slow")) -> Fast | Q26: =_xlfn.XLOOKUP(Orders!B26,'Customer Master'!$A$1:$A$50,'Customer Master'!$B$1:$B$50) -> Benjamin Clark | R26: =_xlfn.XLOOKUP(Orders!C26,'Product Master'!$A$1:$A$23,'Product Master'!$C$1:$C$23) -> Toys | S26: =_xlfn.XLOOKUP(C26,'Product Master'!$A$1:$A$23,'Product Master'!$B$1:$B$23) -> Action Figure | T26: =IF(I26="Delivered",G26,0) -> 43
A27: ORD0026 | B27: CUST027 | C27: PROD022 | D27: South | E27: 64 | F27: 4 | G27: 256 | H27: Debit Card | I27: Delivered | J27: USPS | K27: 45214 | L27: 45220 | N27: =IF(M27<>"","Cancelled","Delivered") -> Delivered | O27: =IF(L27<>"",L27-K27,"NA") -> 6 | P27: =IF(L27="","Cancelled",IF(L27-K27<=2,"Fast","Slow")) -> Slow | Q27: =_xlfn.XLOOKUP(Orders!B27,'Customer Master'!$A$1:$A$50,'Customer Master'!$B$1:$B$50) -> Hazel Brooks | R27: =_xlfn.XLOOKUP(Orders!C27,'Product Master'!$A$1:$A$23,'Product Master'!$C$1:$C$23) -> Fashion | S27: =_xlfn.XLOOKUP(C27,'Product Master'!$A$1:$A$23,'Product Master'!$B$1:$B$23) -> Backpack | T27: =IF(I27="Delivered",G27,0) -> 256
A28: ORD0027 | B28: CUST018 | C28: PROD008 | D28: South | E28: 70 | F28: 2 | G28: 140 | H28: Amazon Pay | I28: In Transit | J28: Amazon Logistics | K28: 44942 | N28: =IF(M28<>"","Cancelled","Delivered") -> Delivered | O28: =IF(L28<>"",L28-K28,"NA") -> NA | P28: =IF(L28="","Cancelled",IF(L28-K28<=2,"Fast","Slow")) -> Cancelled | Q28: =_xlfn.XLOOKUP(Orders!B28,'Customer Master'!$A$1:$A$50,'Customer Master'!$B$1:$B$50) -> Grace Scott | R28: =_xlfn.XLOOKUP(Orders!C28,'Product Master'!$A$1:$A$23,'Product Master'!$C$1:$C$23) -> Books | S28: =_xlfn.XLOOKUP(C28,'Product Master'!$A$1:$A$23,'Product Master'!$B$1:$B$23) -> Textbook | T28: =IF(I28="Delivered",G28,0) -> 0
A29: ORD0028 | B29: CUST018 | C29: PROD018 | D29: Central | E29: 97 | F29: 3 | G29: 291 | H29: Credit Card | I29: In Transit | J29: Amazon Logistics | K29: 45208 | N29: =IF(M29<>"","Cancelled","Delivered") -> Delivered | O29: =IF(L29<>"",L29-K29,"NA") -> NA | P29: =IF(L29="","Cancelled",IF(L29-K29<=2,"Fast","Slow")) -> Cancelled | Q29: =_xlfn.XLOOKUP(Orders!B29,'Customer Master'!$A$1:$A$50,'Customer Master'!$B$1:$B$50) -> Grace Scott | R29: =_xlfn.XLOOKUP(Orders!C29,'Product Master'!$A$1:$A$23,'Product Master'!$C$1:$C$23) -> Toys | S29: =_xlfn.XLOOKUP(C29,'Product Master'!$A$1:$A$23,'Product Master'!$B$1:$B$23) -> Doll House | T29: =IF(I29="Delivered",G29,0) -> 0
A30: ORD0029 | B30: CUST007 | C30: PROD021 | D30: East | E30: 37 | F30: 3 | G30: 111 | H30: Apple Pay | I30: Cancelled | J30: DHL | K30: 45206 | M30: 45209 | N30: =IF(M30<>"","Cancelled","Delivered") -> Cancelled | O30: =IF(L30<>"",L30-K30,"NA") -> NA | P30: =IF(L30="","Cancelled",IF(L30-K30<=2,"Fast","Slow")) -> Cancelled | Q30: =_xlfn.XLOOKUP(Orders!B30,'Customer Master'!$A$1:$A$50,'Customer Master'!$B$1:$B$50) -> Liam Walker | R30: =_xlfn.XLOOKUP(Orders!C30,'Product Master'!$A$1:$A$23,'Product Master'!$C$1:$C$23) -> Home | S30: =_xlfn.XLOOKUP(C30,'Product Master'!$A$1:$A$23,'Product Master'!$B$1:$B$23) -> Wall Clock | T30: =IF(I30="Delivered",G30,0) -> 0
A31: ORD0030 | B31: CUST008 | C31: PROD008 | D31: North | E31: 69 | F31: 5 | G31: 345 | H31: Amazon Pay | I31: In Transit | J31: Amazon Logistics | K31: 44971 | N31: =IF(M31<>"","Cancelled","Delivered") -> Delivered | O31: =IF(L31<>"",L31-K31,"NA") -> NA | P31: =IF(L31="","Cancelled",IF(L31-K31<=2,"Fast","Slow")) -> Cancelled | Q31: =_xlfn.XLOOKUP(Orders!B31,'Customer Master'!$A$1:$A$50,'Customer Master'!$B$1:$B$50) -> Harper Young | R31: =_xlfn.XLOOKUP(Orders!C31,'Product Master'!$A$1:$A$23,'Product Master'!$C$1:$C$23) -> Books | S31: =_xlfn.XLOOKUP(C31,'Product Master'!$A$1:$A$23,'Product Master'!$B$1:$B$23) -> Textbook | T31: =IF(I31="Delivered",G31,0) -> 0
A32: ORD0031 | B32: CUST014 | C32: PROD002 | D32: North | E32: 42 | F32: 5 | G32: 210 | H32: Amazon Pay | I32: In Transit | J32: UPS | K32: 45011 | N32: =IF(M32<>"","Cancelled","Delivered") -> Delivered | O32: =IF(L32<>"",L32-K32,"NA") -> NA | P32: =IF(L32="","Cancelled",IF(L32-K32<=2,"Fast","Slow")) -> Cancelled | Q32: =_xlfn.XLOOKUP(Orders!B32,'Customer Master'!$A$1:$A$50,'Customer Master'!$B$1:$B$50) -> Harper Young | R32: =_xlfn.XLOOKUP(Orders!C32,'Product Master'!$A$1:$A$23,'Product Master'!$C$1:$C$23) -> Toys | S32: =_xlfn.XLOOKUP(C32,'Product Master'!$A$1:$A$23,'Product Master'!$B$1:$B$23) -> Action Figure | T32: =IF(I32="Delivered",G32,0) -> 0
A33: ORD0032 | B33: CUST037 | C33: PROD009 | D33: East | E33: 11 | F33: 5 | G33: 55 | H33: Debit Card | I33: Cancelled | J33: FedEx | K33: 45092 | M33: 45099 | N33: =IF(M33<>"","Cancelled","Delivered") -> Cancelled | O33: =IF(L33<>"",L33-K33,"NA") -> NA | P33: =IF(L33="","Cancelled",IF(L33-K33<=2,"Fast","Slow")) -> Cancelled | Q33: =_xlfn.XLOOKUP(Orders!B33,'Customer Master'!$A$1:$A$50,'Customer Master'!$B$1:$B$50) -> Emily Johnson | R33: =_xlfn.XLOOKUP(Orders!C33,'Product Master'!$A$1:$A$23,'Product Master'!$C$1:$C$23) -> Books | S33: =_xlfn.XLOOKUP(C33,'Product Master'!$A$1:$A$23,'Product Master'!$B$1:$B$23) -> Magazine | T33: =IF(I33="Delivered",G33,0) -> 0
A34: ORD0033 | B34: CUST016 | C34: PROD005 | D34: South | E34: 27 | F34: 2 | G34: 54 | H34: Apple Pay | I34: Delivered | J34: USPS | K34: 45068 | L34: 45069 | N34: =IF(M34<>"","Cancelled","Delivered") -> Delivered | O34: =IF(L34<>"",L34-K34,"NA") -> 1 | P34: =IF(L34="","Cancelled",IF(L34-K34<=2,"Fast","Slow")) -> Fast | Q34: =_xlfn.XLOOKUP(Orders!B34,'Customer Master'!$A$1:$A$50,'Customer Master'!$B$1:$B$50) -> Elijah Lewis | R34: =_xlfn.XLOOKUP(Orders!C34,'Product Master'!$A$1:$A$23,'Product Master'!$C$1:$C$23) -> Fashion | S34: =_xlfn.XLOOKUP(C34,'Product Master'!$A$1:$A$23,'Product Master'!$B$1:$B$23) -> T-Shirt | T34: =IF(I34="Delivered",G34,0) -> 54
A35: ORD0034 | B35: CUST025 | C35: PROD015 | D35: South | E35: 21 | F35: 1 | G35: 21 | H35: Amazon Pay | I35: In Transit | J35: DHL | K35: 45250 | N35: =IF(M35<>"","Cancelled","Delivered") -> Delivered | O35: =IF(L35<>"",L35-K35,"NA") -> NA | P35: =IF(L35="","Cancelled",IF(L35-K35<=2,"Fast","Slow")) -> Cancelled | Q35: =_xlfn.XLOOKUP(Orders!B35,'Customer Master'!$A$1:$A$50,'Customer Master'!$B$1:$B$50) -> Emma King | R35: =_xlfn.XLOOKUP(Orders!C35,'Product Master'!$A$1:$A$23,'Product Master'!$C$1:$C$23) -> Books | S35: =_xlfn.XLOOKUP(C35,'Product Master'!$A$1:$A$23,'Product Master'!$B$1:$B$23) -> Novel | T35: =IF(I35="Delivered",G35,0) -> 0
A36: ORD0035 | B36: CUST032 | C36: PROD011 | D36: South | E36: 172 | F36: 1 | G36: 172 | H36: PayPal | I36: Delivered | J36: USPS | K36: 45282 | L36: 45286 | N36: =IF(M36<>"","Cancelled","Delivered") -> Delivered | O36: =IF(L36<>"",L36-K36,"NA") -> 4 | P36: =IF(L36="","Cancelled",IF(L36-K36<=2,"Fast","Slow")) -> Slow | Q36: =_xlfn.XLOOKUP(Orders!B36,'Customer Master'!$A$1:$A$50,'Customer Master'!$B$1:$B$50) -> Luke Gray | R36: =_xlfn.XLOOKUP(Orders!C36,'Product Master'!$A$1:$A$23,'Product Master'!$C$1:$C$23) -> Electronics | S36: =_xlfn.XLOOKUP(C36,'Product Master'!$A$1:$A$23,'Product Master'!$B$1:$B$23) -> Headphones | T36: =IF(I36="Delivered",G36,0) -> 172
A37: ORD0036 | B37: CUST014 | C37: PROD016 | D37: North | E37: 212 | F37: 3 | G37: 636 | H37: Amazon Pay | I37: In Transit | J37: UPS | K37: 45130 | N37: =IF(M37<>"","Cancelled","Delivered") -> Delivered | O37: =IF(L37<>"",L37-K37,"NA") -> NA | P37: =IF(L37="","Cancelled",IF(L37-K37<=2,"Fast","Slow")) -> Cancelled | Q37: =_xlfn.XLOOKUP(Orders!B37,'Customer Master'!$A$1:$A$50,'Customer Master'!$B$1:$B$50) -> Harper Young | R37: =_xlfn.XLOOKUP(Orders!C37,'Product Master'!$A$1:$A$23,'Product Master'!$C$1:$C$23) -> Home | S37: =_xlfn.XLOOKUP(C37,'Product Master'!$A$1:$A$23,'Product Master'!$B$1:$B$23) -> Cookware Set Pro | T37: =IF(I37="Delivered",G37,0) -> 0
A38: ORD0037 | B38: CUST044 | C38: PROD002 | D38: East | E38: 41 | F38: 4 | G38: 164 | H38: Credit Card | I38: Delivered | J38: Amazon Logistics | K38: 45216 | L38: 45221 | N38: =IF(M38<>"","Cancelled","Delivered") -> Delivered | O38: =IF(L38<>"",L38-K38,"NA") -> 5 | P38: =IF(L38="","Cancelled",IF(L38-K38<=2,"Fast","Slow")) -> Slow | Q38: =_xlfn.XLOOKUP(Orders!B38,'Customer Master'!$A$1:$A$50,'Customer Master'!$B$1:$B$50) -> Grace Ward | R38: =_xlfn.XLOOKUP(Orders!C38,'Product Master'!$A$1:$A$23,'Product Master'!$C$1:$C$23) -> Toys | S38: =_xlfn.XLOOKUP(C38,'Product Master'!$A$1:$A$23,'Product Master'!$B$1:$B$23) -> Action Figure | T38: =IF(I38="Delivered",G38,0) -> 164
A39: ORD0038 | B39: CUST028 | C39: PROD007 | D39: North | E39: 32 | F39: 2 | G39: 64 | H39: Debit Card | I39: Cancelled | J39: FedEx | K39: 45160 | M39: 45162 | N39: =IF(M39<>"","Cancelled","Delivered") -> Cancelled | O39: =IF(L39<>"",L39-K39,"NA") -> NA | P39: =IF(L39="","Cancelled",IF(L39-K39<=2,"Fast","Slow")) -> Cancelled | Q39: =_xlfn.XLOOKUP(Orders!B39,'Customer Master'!$A$1:$A$50,'Customer Master'!$B$1:$B$50) -> Lily Bennett | R39: =_xlfn.XLOOKUP(Orders!C39,'Product Master'!$A$1:$A$23,'Product Master'!$C$1:$C$23) -> Toys | S39: =_xlfn.XLOOKUP(C39,'Product Master'!$A$1:$A$23,'Product Master'!$B$1:$B$23) -> Puzzle | T39: =IF(I39="Delivered",G39,0) -> 0
A40: ORD0039 | B40: CUST024 | C40: PROD022 | D40: East | E40: 66 | F40: 2 | G40: 132 | H40: Apple Pay | I40: In Transit | J40: DHL | K40: 45262 | N40: =IF(M40<>"","Cancelled","Delivered") -> Delivered | O40: =IF(L40<>"",L40-K40,"NA") -> NA | P40: =IF(L40="","Cancelled",IF(L40-K40<=2,"Fast","Slow")) -> Cancelled | Q40: =_xlfn.XLOOKUP(Orders!B40,'Customer Master'!$A$1:$A$50,'Customer Master'!$B$1:$B$50) -> Scarlett Murphy | R40: =_xlfn.XLOOKUP(Orders!C40,'Product Master'!$A$1:$A$23,'Product Master'!$C$1:$C$23) -> Fashion | S40: =_xlfn.XLOOKUP(C40,'Product Master'!$A$1:$A$23,'Product Master'!$B$1:$B$23) -> Backpack | T40: =IF(I40="Delivered",G40,0) -> 0
...

Sheet Product Master
A1: Product ID | B1: Product Name | C1: Category | D1: Cost Price | E1: Description
A2: PROD001 | B2: Smartphone | C2: Electronics | D2: 749 | E2: Latest model with 5G, dual SIM, and OLED display
A3: PROD002 | B3: Action Figure | C3: Toys | D3: 39 | E3: Collectible superhero action figure for ages 8+
A4: PROD003 | B4: Cookware Set | C4: Home | D4: 129 | E4: Non-stick 5-piece cookware set for daily use
A5: PROD004 | B5: Leg Set | C5: Toys | D5: 59 | E5: 300-piece creative building block toy set
A6: PROD005 | B6: T-Shirt | C6: Fashion | D6: 25 | E6: Cotton t-shirt, available in multiple colors
A7: PROD006 | B7: Shoes | C7: Fashion | D7: 89 | E7: Casual wear shoes for men and women
A8: PROD007 | B8: Puzzle | C8: Toys | D8: 29 | E8: 1000-piece jigsaw puzzle
A9: PROD008 | B9: Textbook | C9: Books | D9: 65 | E9: University-level textbook on computer science
A10: PROD009 | B10: Magazine | C10: Books | D10: 10 | E10: Monthly lifestyle magazine
A11: PROD010 | B11: Jeans | C11: Fashion | D11: 55 | E11: Slim fit denim jeans with stretch
A12: PROD011 | B12: Headphones | C12: Electronics | D12: 159 | E12: Wireless noise-cancelling over-ear headphones
A13: PROD012 | B13: Lamp | C13: Home | D13: 42 | E13: LED desk lamp with dimmable light
... A23: PROD022 | B23: Backpack | C23: Fashion | D23: 60 | E23: Waterproof backpack with laptop compartment

Sheet Region Master
A1: Region | B1: Sales Target
A2: Central | B2: 97500
A3: East | B3: 50500
A4: North | B4: 105000
A5: South | B5: 91500
A6: West | B6: 90750

Sheet Customer Master
A1: Customer ID | B1: Customer Name | C1: Customer Type | D1: City | E1: State
A2: CUST001 | B2: James Miller | C2: Business | D2: New York | E2: New York
A3: CUST002 | B3: Emily Johnson | C3: Prime | D3: Seattle | E3: Washington
A4: CUST003 | B4: Ethan Davis | C4: Prime | D4: Austin | E4: Texas
A5: CUST004 | B5: Noah Wilson | C5: Prime | D5: San Francisco | E5: California
A6: CUST005 | B6: Olivia Martinez | C6: Prime | D6: Seattle | E6: Washington
A7: CUST006 | B7: Ava Robinson | C7: Prime | D7: Chicago | E7: Illinois
A8: CUST007 | B8: Liam Walker | C8: Prime | D8: San Francisco | E8: California
A9: CUST008 | B9: Harper Young | C9: Business | D9: Dallas | E9: Texas
A10: CUST009 | B10: Jackson Allen | C10: Business | D10: Seattle | E10: Washington
A11: CUST010 | B11: Charlotte Harris | C11: Prime | D11: Chicago | E11: Illinois
A12: CUST011 | B12: Mason Hall | C12: Business | D12: Miami | E12: Florida
... A50: CUST049 | B50: Hazel Gray | C50: Business | D50: Chicago | E50: Illinois
